<robot name="simple_arm" xmlns:xacro="http://wiki.ros.org/xacro">
    <link name="base_link">
        <visual>
            <geometry>
                <cylinder radius="1" length="0.5" />
            </geometry>
            <material name="blue">
                <color rgba="0 0 1 1" />
            </material>
        </visual>
        <collision>
            <geometry>
                <cylinder radius="1" length="0.5" />
            </geometry>
        </collision>
        <inertial>
            <mass value="0.1" />
            <origin xyz="0 0 0" rpy="0 0 0" />
            <inertia ixx="0.03" iyy="0.03" izz="0.03" ixy="0.0" ixz="0.0" iyz="0.0" />
        </inertial>
    </link>
    <joint name="joint0" type="fixed">
        <parent link="base_link" />
        <child link="gray" />
        <origin xyz="0 0 0.5" />
        <axis xyz="0 0 1" />
        <limit effort="5" velocity="2.0" lower="0" upper="3.14" />
    </joint>
    <link name="gray">
        <visual>
            <origin xyz="0 0 0.5" rpy="0 0 0" />
            <geometry>
                <cylinder radius="0.7" length="1.5" />
            </geometry>
            <material name="gray">
                <color rgba="0.5 0.5 0.5 1" />
            </material>
        </visual>
        <collision>
            <origin xyz="0 0 0.5" rpy="0 0 0" />
            <geometry>
                <cylinder radius="0.7" length="1.5" />
            </geometry>
        </collision>
        <inertial>
            <mass value="0.1" />
            <origin xyz="0 0 0" rpy="0 0 0" />
            <inertia ixx="0.03" iyy="0.03" izz="0.03" ixy="0.0" ixz="0.0" iyz="0.0" />
        </inertial>
    </link>
    <joint name="joint1" type="revolute">
        <parent link="gray" />
        <child link="red" />
        <origin xyz="0 0 1.25" />
        <axis xyz="0 0 1" />
        <limit effort="5" velocity="2.0" lower="0" upper="3.14" />
    </joint>
    <link name="red">
        <visual>
            <origin xyz="0 0 0.75" rpy="0 0 0" />
            <geometry>
                <cylinder radius="0.7" length="1.5" />
            </geometry>
            <material name="red">
                <color rgba="1 0 0 1" />
            </material>
        </visual>
        <collision>
            <origin xyz="0 0 0.75" rpy="0 0 0" />
            <geometry>
                <cylinder radius="0.7" length="1.5" />
            </geometry>
        </collision>
        <inertial>
            <mass value="0.1" />
            <origin xyz="0 0 0" rpy="0 0 0" />
            <inertia ixx="0.03" iyy="0.03" izz="0.03" ixy="0.0" ixz="0.0" iyz="0.0" />
        </inertial>
    </link>
    <joint name="joint01" type="revolute">
        <parent link="red" />
        <child link="purple" />
        <origin xyz="0 0 1.5" />
        <axis xyz="1 0 0" />
        <limit effort="5" velocity="2.0" lower="0" upper="1.77" />
    </joint>
    <link name="purple">
        <visual>
            <origin xyz="0 0 1.5" rpy="0 0 0" />
            <geometry>
                <box size="1.2 1.2 3" />
            </geometry>
            <material name="purple">
                <color rgba="0.8 0 0.8 1" />
            </material>
        </visual>
        <collision>
            <origin xyz="0 0 1.5" rpy="0 0 0" />
            <geometry>
                <box size="1.2 1.2 3" />
            </geometry>
        </collision>
        <inertial>
            <mass value="0.1" />
            <origin xyz="0 0 0" rpy="0 0 0" />
            <inertia ixx="0.03" iyy="0.03" izz="0.03" ixy="0.0" ixz="0.0" iyz="0.0" />
        </inertial>
    </link>
    <joint name="joint2" type="revolute">
        <parent link="purple" />
        <child link="green" />
        <origin xyz="0 0 3" />
        <axis xyz="1 0 0" />
        <limit effort="5" velocity="2.0" lower="0" upper="1.77" />
    </joint>
    <link name="green">
        <visual>
            <origin xyz="0 0 0.5" rpy="0 0 0" />
            <geometry>
                <cylinder radius="0.5" length="1" />
            </geometry>
            <material name="green">
                <color rgba="0 1 0 1" />
            </material>
        </visual>
        <collision>
            <origin xyz="0 0 0.5" rpy="0 0 0" />
            <geometry>
                <cylinder radius="0.5" length="1" />
            </geometry>
        </collision>
        <inertial>
            <mass value="0.1" />
            <origin xyz="0 0 0" rpy="0 0 0" />
            <inertia ixx="0.03" iyy="0.03" izz="0.03" ixy="0.0" ixz="0.0" iyz="0.0" />
        </inertial>
    </link>
    <joint name="joint3" type="revolute">
        <parent link="green" />
        <child link="yellow" />
        <origin xyz="0 0 1" />
        <axis xyz="0 0 1" />
        <limit effort="5" velocity="2.0" lower="0" upper="3.14" />
    </joint>
    <link name="yellow">
        <visual>
            <origin xyz="0 0 0.5" rpy="0 0 0" />
            <geometry>
                <cylinder radius="0.5" length="1" />
            </geometry>
            <material name="yellow">
                <color rgba="1 1 0 1" />
            </material>
        </visual>
        <collision>
            <origin xyz="0 0 0.5" rpy="0 0 0" />
            <geometry>
                <cylinder radius="0.5" length="1" />
            </geometry>
        </collision>
        <inertial>
            <mass value="0.1" />
            <origin xyz="0 0 0" rpy="0 0 0" />
            <inertia ixx="0.03" iyy="0.03" izz="0.03" ixy="0.0" ixz="0.0" iyz="0.0" />
        </inertial>
    </link>
    <joint name="joint4" type="revolute">
        <parent link="yellow" />
        <child link="orange" />
        <origin xyz="0 0 1" />
        <axis xyz="1 0 0" />
        <limit effort="5" velocity="2.0" lower="0" upper="1.77" />
    </joint>
    <link name="orange">
        <visual>
            <origin xyz="0 0 0.4" rpy="0 0 0" />
            <geometry>
                <box size="0.8 0.8 0.8" />
            </geometry>
            <material name="orange">
                <color rgba="1 0.5 0 1" />
            </material>
        </visual>
        <collision>
            <origin xyz="0 0 0.4" rpy="0 0 0" />
            <geometry>
                <box size="0.8 0.8 0.8" />
            </geometry>
        </collision>
        <inertial>
            <mass value="0.1" />
            <origin xyz="0 0 0" rpy="0 0 0" />
            <inertia ixx="0.03" iyy="0.03" izz="0.03" ixy="0.0" ixz="0.0" iyz="0.0" />
        </inertial>
    </link>
    <joint name="joint5" type="revolute">
        <parent link="orange" />
        <child link="cyane" />
        <origin xyz="0 0 0.8" />
        <axis xyz="0 0 1" />
        <limit effort="5" velocity="2.0" lower="0" upper="3.14" />
    </joint>
    <link name="cyane">
        <visual>
            <origin xyz="0 0 0.35" rpy="0 0 0" />
            <geometry>
                <box size="0.4 0.4 0.7" />
            </geometry>
            <material name="cyane">
                <color rgba="0 1 1 1" />
            </material>
        </visual>
        <collision>
            <origin xyz="0 0 0.35" rpy="0 0 0" />
            <geometry>
                <box size="0.4 0.4 0.7" />
            </geometry>
        </collision>
        <inertial>
            <mass value="0.1" />
            <origin xyz="0 0 0" rpy="0 0 0" />
            <inertia ixx="0.03" iyy="0.03" izz="0.03" ixy="0.0" ixz="0.0" iyz="0.0" />
        </inertial>
    </link>
    <joint name="joint6" type="fixed">
        <parent link="cyane" />
        <child link="black" />
        <origin xyz="0 0 0.8" />
        <axis xyz="0 0 1" />
        <limit effort="5" velocity="2.0" lower="0" upper="3.14" />
    </joint>
    <link name="black">
        <visual>
            <origin xyz="0 0 0.1" rpy="0 0 0" />
            <geometry>
                <box size="0.2 0.2 0.4" />
            </geometry>
            <material name="black">
                <color rgba="0 0 0 1" />
            </material>
        </visual>
        <collision>
            <origin xyz="0 0 0.1" rpy="0 0 0" />
            <geometry>
                <box size="0.2 0.2 0.4" />
            </geometry>
        </collision>
        <inertial>
            <mass value="0.1" />
            <origin xyz="0 0 0" rpy="0 0 0" />
            <inertia ixx="0.03" iyy="0.03" izz="0.03" ixy="0.0" ixz="0.0" iyz="0.0" />
        </inertial>
    </link>
    <joint name="joint7" type="prismatic">
        <parent link="black" />
        <child link="magenta1" />
        <origin xyz="0 0 0.3" />
        <axis xyz="1 0 0" />
        <limit effort="5" velocity="2.0" lower="0" upper="0.25" />
    </joint>
    <link name="magenta1">
        <visual>
            <origin xyz="0.1 0 0.25" rpy="0 0 0" />
            <geometry>
                <box size="0.05 0.2 0.5" />
            </geometry>
            <material name="magenta">
                <color rgba="1 0 0.5 1" />
            </material>
        </visual>
        <collision>
            <origin xyz="0.1 0 0.25" rpy="0 0 0" />
            <geometry>
                <box size="0.05 0.2 0.5" />
            </geometry>
        </collision>
        <inertial>
            <mass value="0.1" />
            <origin xyz="0 0 0" rpy="0 0 0" />
            <inertia ixx="0.03" iyy="0.03" izz="0.03" ixy="0.0" ixz="0.0" iyz="0.0" />
        </inertial>
    </link>
    <link name="magenta2">
        <visual>
            <origin xyz="-0.1 0 0.25" rpy="0 0 0" />
            <geometry>
                <box size="0.05 0.2 0.5" />
            </geometry>
            <material name="magenta">
                <color rgba="1 0 0.5 1" />
            </material>
        </visual>
        <collision>
            <origin xyz="-0.1 0 0.25" rpy="0 0 0" />
            <geometry>
                <box size="0.05 0.2 0.5" />
            </geometry>
        </collision>
        <inertial>
            <mass value="0.1" />
            <origin xyz="0 0 0" rpy="0 0 0" />
            <inertia ixx="0.03" iyy="0.03" izz="0.03" ixy="0.0" ixz="0.0" iyz="0.0" />
        </inertial>
    </link>
    <joint name="joint8" type="prismatic">
        <parent link="black" />
        <child link="magenta2" />
        <origin xyz="0 0 0.3" />
        <axis xyz="-1 0 0" />
        <child link="magenta2" />
        <limit effort="5" velocity="2.0" lower="0" upper="0.25" />
        <mimic joint="joint7" multiplier="1" offset="0" />
    </joint>
    <transmission name="trans_joint1">
        <type>transmission_interface/SimpleTransmission</type>
        <joint name="joint1">
            <hardwareInterface>hardware_interface/EffortJointInterface</hardwareInterface>
        </joint>
        <actuator name="joint1_motor">
            <hardwareInterface>hardware_interface/EffortJointInterface</hardwareInterface>
            <mechanicalReduction>1</mechanicalReduction>
        </actuator>
    </transmission>
    <transmission name="trans_joint01">
        <type>transmission_interface/SimpleTransmission</type>
        <joint name="joint01">
            <hardwareInterface>hardware_interface/EffortJointInterface</hardwareInterface>
        </joint>
        <actuator name="joint01_motor">
            <hardwareInterface>hardware_interface/EffortJointInterface</hardwareInterface>
            <mechanicalReduction>1</mechanicalReduction>
        </actuator>
    </transmission>
    <transmission name="trans_joint2">
        <type>transmission_interface/SimpleTransmission</type>
        <joint name="joint2">
            <hardwareInterface>hardware_interface/EffortJointInterface</hardwareInterface>
        </joint>
        <actuator name="joint2_motor">
            <hardwareInterface>hardware_interface/EffortJointInterface</hardwareInterface>
            <mechanicalReduction>1</mechanicalReduction>
        </actuator>
    </transmission>
    <transmission name="trans_joint3">
        <type>transmission_interface/SimpleTransmission</type>
        <joint name="joint3">
            <hardwareInterface>hardware_interface/EffortJointInterface</hardwareInterface>
        </joint>
        <actuator name="joint3_motor">
            <hardwareInterface>hardware_interface/EffortJointInterface</hardwareInterface>
            <mechanicalReduction>1</mechanicalReduction>
        </actuator>
    </transmission>
    <transmission name="trans_joint4">
        <type>transmission_interface/SimpleTransmission</type>
        <joint name="joint4">
            <hardwareInterface>hardware_interface/EffortJointInterface</hardwareInterface>
        </joint>
        <actuator name="joint4_motor">
            <hardwareInterface>hardware_interface/EffortJointInterface</hardwareInterface>
            <mechanicalReduction>1</mechanicalReduction>
        </actuator>
    </transmission>
    <transmission name="trans_joint5">
        <type>transmission_interface/SimpleTransmission</type>
        <joint name="joint5">
            <hardwareInterface>hardware_interface/EffortJointInterface</hardwareInterface>
        </joint>
        <actuator name="joint5_motor">
            <hardwareInterface>hardware_interface/EffortJointInterface</hardwareInterface>
            <mechanicalReduction>1</mechanicalReduction>
        </actuator>
    </transmission>
    <transmission name="trans_joint7">
        <type>transmission_interface/SimpleTransmission</type>
        <joint name="joint7">
            <hardwareInterface>hardware_interface/EffortJointInterface</hardwareInterface>
        </joint>
        <actuator name="joint7_motor">
            <hardwareInterface>hardware_interface/EffortJointInterface</hardwareInterface>
            <mechanicalReduction>1</mechanicalReduction>
        </actuator>
    </transmission>
    <transmission name="trans_joint8">
        <type>transmission_interface/SimpleTransmission</type>
        <joint name="joint8">
            <hardwareInterface>hardware_interface/EffortJointInterface</hardwareInterface>
        </joint>
        <actuator name="joint8_motor">
            <hardwareInterface>hardware_interface/EffortJointInterface</hardwareInterface>
            <mechanicalReduction>1</mechanicalReduction>
        </actuator>
    </transmission>
    <gazebo>
        <plugin name="gazebo_ros_control" filename="libgazebo_ros_control.so">
            <robotNamespace>/</robotNamespace>
        </plugin>
    </gazebo>
</robot>

