<robot name="simple_arm" xmlns:xacro="http://wiki.ros.org/xacro">

    <link name="base_link">
        <visual>
            <geometry>
                <cylinder radius="0.7" length="3.5"/>
            </geometry>
            <material name="gray">
                <color rgba="0.5 0.5 0.5 1"/>
            </material>
        </visual>
    </link>
    
    <joint name="joint1" type="revolute">
        <parent link="base_link"/>
        <child link="link1"/>
        <origin xyz="0 0 1.75"/>
        <axis xyz="0 0 1"/>
        <limit effort="5" velocity="2.0" lower="0" upper="3.14"/>
    </joint>
    
    <link name="link1">
        <visual>
            <geometry>
                <box size="0.6 0.6 3"/>
            </geometry>
            <material name="blue">
                <color rgba="0 0 1 1"/>
            </material>
        </visual>
    </link>
    
    <joint name="joint2" type="revolute">
        <parent link="link1"/>
        <child link="link2"/>
        <origin xyz="0 0 1.5"/>
        <axis xyz="0 0 1"/>
        <limit effort="5" velocity="2.0" lower="0" upper="3.14"/>
    </joint>
    
    <link name="link2">
        <visual>
            <geometry>
                <cylinder radius="0.5" length="2"/>
            </geometry>
            <material name="blue">
                <color rgba="0 0 1 1"/>
            </material>
        </visual>
    </link>
</robot>
